<?xml version="1.0" encoding="utf-8"?>
<robot name="vacuum_robot">

  <!-- Materials -->
  <material name="casing">
    <color rgba="0.1792 0.1792 0.1792 1" />
  </material>
  <material name="gold">
    <color rgba="0.6784 0.4344 0.1764 1" />
  </material>
  <material name="matt_plastic">
    <color rgba="0 0 0 1" />
  </material>
  <material name="led">
    <color rgba="0.1792 1 0 1" />
  </material>
  <material name="rubber">
    <color rgba="0.2358 0.2358 0.2358 1" />
  </material>

  <!-- Links -->
  <link name="base_link" />
  <link name="base">
    <inertial>
      <origin rpy="0 0 0" xyz="0 0 0.05" />
      <mass value="2.9" />
      <inertia ixx="0.0058840261772275" ixy="0" ixz="0" iyy="0.0058840261772275" iyz="0" izz="0.0111680533736944" />
    </inertial>
    <visual name="base">
      <origin rpy="0 0 -1.570796" xyz="0 0 0.02" />
      <geometry>
        <mesh filename="package://vacuum_robot/meshes/base.obj" scale="0.001 0.001 0.001" />
      </geometry>
      <material name="casing"/>
    </visual>
    <visual name="base_ring">
      <origin rpy="0 0 0" xyz="0 0 0.076" />
      <geometry>
        <mesh filename="package://vacuum_robot/meshes/base_ring.obj" scale="0.001 0.001 0.001" />
      </geometry>
      <material name="gold"/>
    </visual>
    <collision>
      <origin xyz="0 0 0.05" />
      <geometry>
        <cylinder length="0.06" radius="0.15" />
      </geometry>
    </collision>
  </link>
  <link name="status_led">
    <inertial>
      <origin rpy="0 0 0" xyz="0 0 0.0025" />
      <mass value="0.01" />
      <inertia ixx="8.28780866868328E-06" ixy="0" ixz="0" iyy="8.28780866868328E-06" iyz="0" izz="1.24089465316501E-05" />
    </inertial>
    <visual>
      <origin rpy="0 0 0" />
      <geometry>
        <mesh filename="package://vacuum_robot/meshes/status_led.obj" scale="0.001 0.001 0.001" />
      </geometry>
      <material name="led"/>
    </visual>
    <collision>
      <origin xyz="0 0 0.0025" />
      <geometry>
        <cylinder length="0.005" radius="0.005" />
      </geometry>
    </collision>
  </link>
  <link name="power_button">
    <inertial>
      <origin rpy="0 0 0" xyz="0 0 0.0025" />
      <mass value="0.01" />
      <inertia ixx="2.69012289209059E-05" ixy="0" ixz="0" iyy="2.69012289209059E-05" iyz="0" izz="4.96357861266006E-05" />
    </inertial>
    <visual>
      <geometry>
        <mesh filename="package://vacuum_robot/meshes/power_button.obj" scale="0.001 0.001 0.001" />
      </geometry>
      <material name="casing"/>
    </visual>
    <collision>
      <origin xyz="0 0 0.0025" />
      <geometry>
        <cylinder length="0.005" radius="0.01" />
      </geometry>
    </collision>
  </link>
  <link name="left_wheel">
    <inertial>
      <origin rpy="0 0 0" xyz="0 0 0" />
      <mass value="0.3" />
      <inertia ixx="0.000256694474956021" ixy="0" ixz="0" iyy="0.000446722202468663" iyz="0" izz="0.000256694358540699" />
    </inertial>
    <visual name="wheel">
      <origin rpy="1.570796 0 0" xyz="0 0.01 0" />
      <geometry>
        <mesh filename="package://vacuum_robot/meshes/wheel.obj" scale="0.001 0.001 0.001" />
      </geometry>
      <material name="matt_plastic"/>
    </visual>
    <visual name="tire">
      <origin rpy="1.570796 0 0" xyz="0 0.01 0" />
      <geometry>
        <mesh filename="package://vacuum_robot/meshes/tire.obj" scale="0.001 0.001 0.001" />
      </geometry>
      <material name="rubber"/>
    </visual>
    <collision>
      <origin rpy="1.570796 0 0" />
      <geometry>
        <cylinder length="0.02" radius="0.03" />
      </geometry>
    </collision>
  </link>
  <link name="right_wheel">
    <inertial>
      <origin rpy="0 0 0" xyz="0 0 0" />
      <mass value="0.3" />
      <inertia ixx="0.000256694474956021" ixy="0" ixz="0" iyy="0.000446722202468663" iyz="0" izz="0.000256694358540699" />
    </inertial>
    <visual name="wheel">
      <origin rpy="1.570796 0 0" xyz="0 0.01 0" />
      <geometry>
        <mesh filename="package://vacuum_robot/meshes/wheel.obj" scale="0.001 0.001 0.001" />
      </geometry>
      <material name="matt_plastic"/>
    </visual>
    <visual name="tire">
      <origin rpy="1.570796 0 0" xyz="0 0.01 0" />
      <geometry>
        <mesh filename="package://vacuum_robot/meshes/tire.obj" scale="0.001 0.001 0.001" />
      </geometry>
      <material name="rubber"/>
    </visual>
    <collision>
      <origin rpy="1.570796 0 0" />
      <geometry>
        <cylinder length="0.02" radius="0.03" />
      </geometry>
    </collision>
  </link>
  <link name="bearing_support_wheel">
    <inertial>
      <origin rpy="0 0 0" xyz="0 0 -0.0105" />
      <mass value="0.1" />
      <inertia ixx="6.15678873145953E-05" ixy="0" ixz="0" iyy="6.15678873145953E-05" iyz="0" izz="4.96357824886218E-05" />
    </inertial>
    <visual>
      <origin rpy="0 0 0" />
      <geometry>
        <mesh filename="package://vacuum_robot/meshes/bearing_support_wheel.obj" scale="0.001 0.001 0.001" />
      </geometry>
      <material name="matt_plastic"/>
    </visual>
    <collision>
      <origin xyz="0 0 -0.0105" />
      <geometry>
        <cylinder length="0.021" radius="0.01" />
      </geometry>
    </collision>
  </link>
  <link name="support_wheel">
    <inertial>
      <origin rpy="0 0 0" xyz="0 0 0" />
      <mass value="0.01" />
      <inertia ixx="1.00000006568735E-05" ixy="0" ixz="0" iyy="1.00000006568735E-05" iyz="0" izz="1.00000006568735E-05" />
    </inertial>
    <visual>
      <geometry>
        <mesh filename="package://vacuum_robot/meshes/support_wheel.obj" scale="0.001 0.001 0.001" />
      </geometry>
      <material name="rubber"/>
    </visual>
    <collision>
      <geometry>
        <sphere radius="0.005" />
      </geometry>
    </collision>
  </link>
  <link name="lidar_casing">
    <inertial>
      <origin rpy="0 0 0" xyz="0 0 0.015" />
      <mass value="0.15" />
      <inertia ixx="0.000298361119348556" ixy="0" ixz="0" iyy="0.000298361119348556" iyz="0" izz="0.000446722115157172" />
    </inertial>
    <visual name="lidar_casing_side">
      <origin rpy="0 0 0.44" />
      <geometry>
        <mesh filename="package://vacuum_robot/meshes/lidar_casing_side.obj" scale="0.001 0.001 0.001" />
      </geometry>
      <material name="gold"/>
    </visual>
    <visual name="lidar_casing_top">
      <origin xyz="0 0 0.029" />
      <geometry>
        <mesh filename="package://vacuum_robot/meshes/lidar_casing_top.obj" scale="0.001 0.001 0.001" />
      </geometry>
      <material name="casing"/>
    </visual>
    <collision>
      <origin xyz="0 0 0.015" />
      <geometry>
        <cylinder length="0.03" radius="0.03" />
      </geometry>
    </collision>
  </link>
  <link name="lidar">
    <inertial>
      <origin rpy="0 0 0" xyz="0 0 0" />
      <mass value="0.05" />
      <inertia ixx="0.000176284447661601" ixy="0" ixz="0" iyy="0.000176284447661601" iyz="0" izz="0.000285902176983655" />
    </inertial>
    <visual>
      <origin rpy="0 0 1.570796" xyz="0 0 -0.01" />
      <geometry>
        <mesh filename="package://vacuum_robot/meshes/lidar.obj" scale="0.001 0.001 0.001" />
      </geometry>
      <material name="matt_plastic"/>
    </visual>
    <collision>
      <geometry>
        <cylinder length="0.02" radius="0.024" />
      </geometry>
    </collision>
  </link>
  <link name="ir_sensor_front">
    <inertial>
      <origin rpy="0 0 0" xyz="0 0 0.0025" />
      <mass value="0.01" />
      <inertia ixx="8.28780866868328E-06" ixy="0" ixz="0" iyy="8.28780866868328E-06" iyz="0" izz="1.24089465316501E-05" />
    </inertial>
    <visual>
      <geometry>
        <mesh filename="package://vacuum_robot/meshes/ir_sensor.obj" scale="0.001 0.001 0.001" />
      </geometry>
      <material name="matt_plastic"/>
    </visual>
    <collision>
      <origin xyz="0 0 0.0025" />
      <geometry>
        <cylinder length="0.005" radius="0.005" />
      </geometry>
    </collision>
  </link>
  <link name="ir_sensor_front_left">
    <inertial>
      <origin rpy="0 0 0" xyz="0 0 0.0025" />
      <mass value="0.01" />
      <inertia ixx="8.28780866868328E-06" ixy="0" ixz="0" iyy="8.28780866868328E-06" iyz="0" izz="1.24089465316501E-05" />
    </inertial>
    <visual>
      <geometry>
        <mesh filename="package://vacuum_robot/meshes/ir_sensor.obj" scale="0.001 0.001 0.001" />
      </geometry>
      <material name="matt_plastic"/>
    </visual>
    <collision>
      <origin xyz="0 0 0.0025" />
      <geometry>
        <cylinder length="0.005" radius="0.005" />
      </geometry>
    </collision>
  </link>
  <link name="ir_sensor_front_right">
    <inertial>
      <origin rpy="0 0 0" xyz="0 0 0.0025" />
      <mass value="0.01" />
      <inertia ixx="8.28780866868328E-06" ixy="0" ixz="0" iyy="8.28780866868328E-06" iyz="0" izz="1.24089465316501E-05" />
    </inertial>
    <visual>
      <geometry>
        <mesh filename="package://vacuum_robot/meshes/ir_sensor.obj" scale="0.001 0.001 0.001" />
      </geometry>
      <material name="matt_plastic"/>
    </visual>
    <collision>
      <origin xyz="0 0 0.0025" />
      <geometry>
        <cylinder length="0.005" radius="0.005" />
      </geometry>
    </collision>
  </link>
  <link name="ir_sensor_back">
    <inertial>
      <origin rpy="0 0 0" xyz="0 0 0.0025" />
      <mass value="0.01" />
      <inertia ixx="8.28780866868328E-06" ixy="0" ixz="0" iyy="8.28780866868328E-06" iyz="0" izz="1.24089465316501E-05" />
    </inertial>
    <visual>
      <geometry>
        <mesh filename="package://vacuum_robot/meshes/ir_sensor.obj" scale="0.001 0.001 0.001" />
      </geometry>
      <material name="matt_plastic"/>
    </visual>
    <collision>
      <origin xyz="0 0 0.0025" />
      <geometry>
        <cylinder length="0.005" radius="0.005" />
      </geometry>
    </collision>
  </link>
  <link name="ir_sensor_back_left">
    <inertial>
      <origin rpy="0 0 0" xyz="0 0 0.0025" />
      <mass value="0.01" />
      <inertia ixx="8.28780866868328E-06" ixy="0" ixz="0" iyy="8.28780866868328E-06" iyz="0" izz="1.24089465316501E-05" />
    </inertial>
    <visual>
      <geometry>
        <mesh filename="package://vacuum_robot/meshes/ir_sensor.obj" scale="0.001 0.001 0.001" />
      </geometry>
      <material name="matt_plastic"/>
    </visual>
    <collision>
      <origin xyz="0 0 0.0025" />
      <geometry>
        <cylinder length="0.005" radius="0.005" />
      </geometry>
    </collision>
  </link>
  <link name="ir_sensor_back_right">
    <inertial>
      <origin rpy="0 0 0" xyz="0 0 0.0025" />
      <mass value="0.01" />
      <inertia ixx="8.28780866868328E-06" ixy="0" ixz="0" iyy="8.28780866868328E-06" iyz="0" izz="1.24089465316501E-05" />
    </inertial>
    <visual>
      <geometry>
        <mesh filename="package://vacuum_robot/meshes/ir_sensor.obj" scale="0.001 0.001 0.001" />
      </geometry>
      <material name="matt_plastic"/>
    </visual>
    <collision>
      <origin xyz="0 0 0.0025" />
      <geometry>
        <cylinder length="0.005" radius="0.005" />
      </geometry>
    </collision>
  </link>

  <!--Disable_Collisions -->
  <disable_collision link1="base" link2="lidar"/>

  <!-- Joints -->
  <joint name="base_link_base_joint" type="fixed">
    <parent link="base_link"/>
     <child link="base"/>
  </joint>
  <joint name="base_status_led_joint" type="fixed">
    <origin xyz="0 0 0.075" />
    <parent link="base" />
    <child link="status_led" />
  </joint>
  <joint name="base_power_button_joint" type="fixed">
    <origin xyz="-0.1 0 0.075" />
    <parent link="base" />
    <child link="power_button" />
  </joint>
  <joint name="base_left_wheel_joint" type="continuous">
    <origin xyz="0 0.12 0.03" />
    <parent link="base" />
    <child link="left_wheel" />
    <axis xyz="0 1 0" />
    <dynamics damping="0.05" friction="0.05" />
  </joint>
  <joint name="base_right_wheel_joint" type="continuous">
    <origin xyz="0 -0.12 0.03" />
    <parent link="base" />
    <child link="right_wheel" />
    <axis xyz="0 1 0" />
    <dynamics damping="0.05" friction="0.05" />
  </joint>
  <joint name="base_bearing_support_wheel_joint" type="fixed">
    <origin xyz="0.1 0 0.025" />
    <parent link="base" />
    <child link="bearing_support_wheel" />
  </joint>
  <joint name="bearing_support_wheel_support_wheel_joint" type="fixed">
    <origin xyz="0 0 -0.02" />
    <parent link="bearing_support_wheel" />
    <child link="support_wheel" />
  </joint>
  <joint name="base_lidar_casing_joint" type="prismatic">
    <origin xyz="0.1 0 0.05" />
    <parent link="base" />
    <child link="lidar_casing" />
    <axis xyz="0 0 1" />
    <dynamics damping="0.05" friction="0.05" />
    <limit lower="0" upper="0.02" effort="3.40282346638529E+38" velocity="100" />
  </joint>
  <joint name="lidar_casing_lidar_joint" type="continuous">
    <origin xyz="0 0 0.015" />
    <parent link="lidar_casing" />
    <child link="lidar" />
    <axis xyz="0 0 1" />
    <dynamics damping="0.05" friction="0.05" />
  </joint>
  <joint name="base_ir_sensor_front_joint" type="fixed">
    <origin xyz="0.13 0 0.02" />
    <parent link="base" />
    <child link="ir_sensor_front" />
  </joint>
  <joint name="base_ir_sensor_front_left_joint" type="fixed">
    <origin xyz="0.065 0.112583 0.02" />
    <parent link="base" />
    <child link="ir_sensor_front_left" />
  </joint>
  <joint name="base_ir_sensor_front_right_joint" type="fixed">
    <origin xyz="0.065 -0.112583 0.02" />
    <parent link="base" />
    <child link="ir_sensor_front_right" />
  </joint>
  <joint name="base_ir_sensor_back_joint" type="fixed">
    <origin xyz="-0.13 0 0.02" />
    <parent link="base" />
    <child link="ir_sensor_back" />
  </joint>
  <joint name="base_ir_sensor_back_left_joint" type="fixed">
    <origin xyz="-0.065 0.112583 0.02" />
    <parent link="base" />
    <child link="ir_sensor_back_left" />
  </joint>
  <joint name="base_ir_sensor_back_right_joint" type="fixed">
    <origin xyz="-0.065 -0.112583 0.02" />
    <parent link="base" />
    <child link="ir_sensor_back_right" />
  </joint>
</robot>